<?xml version="1.0" encoding="utf-8"?>
<!-- This URDF was automatically created by SolidWorks to URDF Exporter! Originally created by Stephen Brawner (brawner@gmail.com) 
     Commit Version: 1.6.0-1-g15f4949  Build Version: 1.6.7594.29634
     For more information, please see http://wiki.ros.org/sw_urdf_exporter -->
<robot
  name="mybot_description">
  <link
    name="base_link">
    <inertial>
      <origin
        xyz="0.0016313 8.6959E-07 0.044005"
        rpy="0 0 0" />
      <mass
        value="0.48293" />
      <inertia
        ixx="0.0019371"
        ixy="1.7761E-08"
        ixz="5.6275E-06"
        iyy="0.0020939"
        iyz="1.3096E-09"
        izz="0.0038315" />
    </inertial>
    <visual>
      <origin
        xyz="0 0 0"
        rpy="0 0 0" />
      <geometry>
        <mesh
          filename="package://mybot_description/meshes/base_link.STL" />
      </geometry>
      <material
        name="">
        <color
          rgba="0.25098 0.25098 0.25098 1" />
      </material>
    </visual>
    <collision>
      <origin
        xyz="0 0 0"
        rpy="0 0 0" />
      <geometry>
        <mesh
          filename="package://mybot_description/meshes/base_link.STL" />
      </geometry>
    </collision>
  </link>
  <link
    name="wheel_right">
    <inertial>
      <origin
        xyz="-4.3367E-05 0.013911 -0.00036102"
        rpy="0 0 0" />
      <mass
        value="0.085958" />
      <inertia
        ixx="3.7826E-05"
        ixy="-5.0247E-11"
        ixz="4.2853E-09"
        iyy="6.357E-05"
        iyz="-4.1865E-10"
        izz="3.7861E-05" />
    </inertial>
    <visual>
      <origin
        xyz="0 0 0"
        rpy="0 0 0" />
      <geometry>
        <mesh
          filename="package://mybot_description/meshes/wheel_right.STL" />
      </geometry>
      <material
        name="">
        <color
          rgba="0.75294 0.75294 0.75294 1" />
      </material>
    </visual>
    <collision>
      <origin
        xyz="0 0 0"
        rpy="0 0 0" />
      <geometry>
        <mesh
          filename="package://mybot_description/meshes/wheel_right.STL" />
      </geometry>
    </collision>
  </link>
  <joint
    name="wheel_right_jt"
    type="continuous">
    <origin
      xyz="0 -0.0956 0.030497"
      rpy="0 0 0" />
    <parent
      link="base_link" />
    <child
      link="wheel_right" />
    <axis
      xyz="0 -1 0" />
    <limit
      effort="100"
      velocity="100" />
  </joint>
  <link
    name="wheel_left">
    <inertial>
      <origin
        xyz="0.0001873 -0.013911 -0.00031169"
        rpy="0 0 0" />
      <mass
        value="0.085958" />
      <inertia
        ixx="3.7835E-05"
        ixy="-2.1718E-10"
        ixz="-1.599E-08"
        iyy="6.357E-05"
        iyz="3.6142E-10"
        izz="3.7852E-05" />
    </inertial>
    <visual>
      <origin
        xyz="0 0 0"
        rpy="0 0 0" />
      <geometry>
        <mesh
          filename="package://mybot_description/meshes/wheel_left.STL" />
      </geometry>
      <material
        name="">
        <color
          rgba="0 0 0 1" />
      </material>
    </visual>
    <collision>
      <origin
        xyz="0 0 0"
        rpy="0 0 0" />
      <geometry>
        <mesh
          filename="package://mybot_description/meshes/wheel_left.STL" />
      </geometry>
    </collision>
  </link>
  <joint
    name="wheel_left_jt"
    type="continuous">
    <origin
      xyz="0 0.0956 0.030498"
      rpy="0 0 0" />
    <parent
      link="base_link" />
    <child
      link="wheel_left" />
    <axis
      xyz="0 1 0" />
    <limit
      effort="100"
      velocity="100" />
  </joint>
  <link
    name="caster1">
    <inertial>
      <origin
        xyz="-5.5511E-17 -1.3878E-17 -1.3878E-17"
        rpy="0 0 0" />
      <mass
        value="0.0011503" />
      <inertia
        ixx="1.9441E-08"
        ixy="5.3767E-25"
        ixz="6.3848E-25"
        iyy="1.9441E-08"
        iyz="2.0163E-25"
        izz="1.9441E-08" />
    </inertial>
    <visual>
      <origin
        xyz="0 0 0"
        rpy="0 0 0" />
      <geometry>
        <mesh
          filename="package://mybot_description/meshes/caster1.STL" />
      </geometry>
      <material
        name="">
        <color
          rgba="0.64706 0.61961 0.58824 1" />
      </material>
    </visual>
    <collision>
      <origin
        xyz="0 0 0"
        rpy="0 0 0" />
      <geometry>
        <mesh
          filename="package://mybot_description/meshes/caster1.STL" />
      </geometry>
    </collision>
  </link>
  <joint
    name="caster1_jt"
    type="continuous">
    <origin
      xyz="0.09 0 0.00297"
      rpy="0 0 0" />
    <parent
      link="base_link" />
    <child
      link="caster1" />
    <axis
      xyz="1 0 0" />
    <limit
      effort="100"
      velocity="100" />
  </joint>
  <link
    name="caster2">
    <inertial>
      <origin
        xyz="9.8255E-15 -1.3878E-17 -1.3878E-17"
        rpy="0 0 0" />
      <mass
        value="0.0011503" />
      <inertia
        ixx="1.9441E-08"
        ixy="0"
        ixz="0"
        iyy="1.9441E-08"
        iyz="-1.0351E-42"
        izz="1.9441E-08" />
    </inertial>
    <visual>
      <origin
        xyz="0 0 0"
        rpy="0 0 0" />
      <geometry>
        <mesh
          filename="package://mybot_description/meshes/caster2.STL" />
      </geometry>
      <material
        name="">
        <color
          rgba="0.64706 0.61961 0.58824 1" />
      </material>
    </visual>
    <collision>
      <origin
        xyz="0 0 0"
        rpy="0 0 0" />
      <geometry>
        <mesh
          filename="package://mybot_description/meshes/caster2.STL" />
      </geometry>
    </collision>
  </link>
  <joint
    name="caster2_jt"
    type="continuous">
    <origin
      xyz="-0.09 0 0.00297"
      rpy="0 0 0" />
    <parent
      link="base_link" />
    <child
      link="caster2" />
    <axis
      xyz="1 0 0" />
    <limit
      effort="100"
      velocity="100" />
  </joint>
</robot>